<?xml version="1.0" ?>
<!-- =================================================================================== -->
<!-- |    This document was autogenerated by xacro from rizon.urdf.xacro               | -->
<!-- |    EDITING THIS FILE BY HAND IS NOT RECOMMENDED                                 | -->
<!-- =================================================================================== -->
<robot name="rizon4">
  <!-- JOINTS-->
  <joint name="base_joint" type="fixed">
    <parent link="world"/>
    <child link="base_link"/>
    <origin rpy="0.0 0.0 0.0" xyz="0.0 0.0 0.0"/>
  </joint>
  <joint name="joint1" type="revolute">
    <parent link="base_link"/>
    <child link="link1"/>
    <origin rpy="0 0 -3.141592653589793" xyz="0.0 0.0 0.155"/>
    <axis xyz="0 0 1"/>
    <limit effort="123" lower="-2.7925" upper="2.7925" velocity="2.0944"/>
  </joint>
  <joint name="joint2" type="revolute">
    <parent link="link1"/>
    <child link="link2"/>
    <origin rpy="0 0 0" xyz="0.0 0.03 0.210"/>
    <axis xyz="0 1 0"/>
    <limit effort="123" lower="-2.2689" upper="2.2689" velocity="2.0944"/>
  </joint>
  <joint name="joint3" type="revolute">
    <parent link="link2"/>
    <child link="link3"/>
    <origin rpy="0 0 0" xyz="0.0 0.035 0.205"/>
    <axis xyz="0 0 1"/>
    <limit effort="64" lower="-2.9671" upper="2.9671" velocity="2.4435"/>
  </joint>
  <joint name="joint4" type="revolute">
    <parent link="link3"/>
    <child link="link4"/>
    <origin rpy="0 0 -3.141592653589793" xyz="-0.02 -0.03 0.19"/>
    <axis xyz="0 1 0"/>
    <limit effort="64" lower="-1.8675" upper="2.6878" velocity="2.4435"/>
  </joint>
  <joint name="joint5" type="revolute">
    <parent link="link4"/>
    <child link="link5"/>
    <origin rpy="0 0 -3.141592653589793" xyz="-0.02 0.025 0.195"/>
    <axis xyz="0 0 1"/>
    <limit effort="39" lower="-2.9671" upper="2.9671" velocity="4.8869"/>
  </joint>
  <joint name="joint6" type="revolute">
    <parent link="link5"/>
    <child link="link6"/>
    <origin rpy="0 0 0" xyz="0.0 0.03 0.19"/>
    <axis xyz="0 1 0"/>
    <limit effort="39" lower="-1.3963" upper="4.5379" velocity="4.8869"/>
  </joint>
  <joint name="joint7" type="revolute">
    <parent link="link6"/>
    <child link="link7"/>
    <origin rpy="0 -1.5707963267948966 0" xyz="-0.055 0.070 0.11"/>
    <axis xyz="0 0 1"/>
    <limit effort="39" lower="-2.9671" upper="2.9671" velocity="4.8869"/>
  </joint>
  <joint name="link7_to_flange" type="fixed">
    <parent link="link7"/>
    <child link="flange"/>
    <origin rpy="0 0 -3.141592653589793" xyz="0.0 0.0 0.081"/>
  </joint>
  <!-- LINKS -->
  <link name="world">
    </link>
  <link name="base_link">
    <inertial>
      <mass value="3.7"/>
      <origin rpy="0 0 0" xyz="0.0 -0.0 0.09"/>
      <inertia ixx="0.02" ixy="0.0" ixz="0.0" iyy="0.02" iyz="0.0" izz="0.01"/>
    </inertial>
    <visual>
      <origin rpy="0 0 0" xyz="0 0 0"/>
      <geometry>
        <mesh filename="../meshes/link0.obj"/>
      </geometry>
      <material name="rizon_light_grey"/>
    </visual>
    <collision>
      <origin rpy="0 0 0" xyz="0 0 0"/>
      <geometry>
        <mesh filename="../meshes/link0_collision.stl"/>
      </geometry>
    </collision>
  </link>
  <link name="link1">
    <inertial>
      <mass value="3.7"/>
      <origin rpy="0 0 0" xyz="0.0 0.01 0.15"/>
      <inertia ixx="0.03" ixy="0.0" ixz="0.0" iyy="0.03" iyz="0.0" izz="0.01"/>
    </inertial>
    <visual>
      <origin rpy="0 0 0" xyz="0 0 0"/>
      <geometry>
        <mesh filename="../meshes/link1.obj"/>
      </geometry>
      <material name="rizon_light_grey"/>
    </visual>
    <collision>
      <origin rpy="0 0 0" xyz="0 0 0"/>
      <geometry>
        <mesh filename="../meshes/link1_collision.stl"/>
      </geometry>
    </collision>
  </link>
  <link name="link2">
    <inertial>
      <mass value="2.7"/>
      <origin rpy="0 0 0" xyz="0.0 0.04 0.1"/>
      <inertia ixx="0.02" ixy="0.0" ixz="0.0" iyy="0.02" iyz="-0.0" izz="0.0"/>
    </inertial>
    <visual>
      <origin rpy="0 0 0" xyz="0 0 0"/>
      <geometry>
        <mesh filename="../meshes/link2.obj"/>
      </geometry>
      <material name="rizon_light_grey"/>
    </visual>
    <collision>
      <origin rpy="0 0 0" xyz="0 0 0"/>
      <geometry>
        <mesh filename="../meshes/link2_collision.stl"/>
      </geometry>
    </collision>
  </link>
  <link name="link3">
    <inertial>
      <mass value="2.4"/>
      <origin rpy="0 0 0" xyz="-0.01 -0.0 0.13"/>
      <inertia ixx="0.01" ixy="0.0" ixz="-0.0" iyy="0.01" iyz="-0.0" izz="0.0"/>
    </inertial>
    <visual>
      <origin rpy="0 0 0" xyz="0 0 0"/>
      <geometry>
        <mesh filename="../meshes/link3.obj"/>
      </geometry>
      <material name="rizon_light_grey"/>
    </visual>
    <collision>
      <origin rpy="0 0 0" xyz="0 0 0"/>
      <geometry>
        <mesh filename="../meshes/link3_collision.stl"/>
      </geometry>
    </collision>
  </link>
  <link name="link4">
    <inertial>
      <mass value="2.4"/>
      <origin rpy="0 0 0" xyz="-0.01 0.03 0.1"/>
      <inertia ixx="0.02" ixy="0.0" ixz="-0.0" iyy="0.02" iyz="-0.0" izz="0.0"/>
    </inertial>
    <visual>
      <origin rpy="0 0 0" xyz="0 0 0"/>
      <geometry>
        <mesh filename="../meshes/link4.obj"/>
      </geometry>
      <material name="rizon_light_grey"/>
    </visual>
    <collision>
      <origin rpy="0 0 0" xyz="0 0 0"/>
      <geometry>
        <mesh filename="../meshes/link4_collision.stl"/>
      </geometry>
    </collision>
  </link>
  <link name="link5">
    <inertial>
      <mass value="2.4"/>
      <origin rpy="0 0 0" xyz="0.0 0.0 0.13"/>
      <inertia ixx="0.01" ixy="0.0" ixz="0.0" iyy="0.01" iyz="0.0" izz="0.0"/>
    </inertial>
    <visual>
      <origin rpy="0 0 0" xyz="0 0 0"/>
      <geometry>
        <mesh filename="../meshes/link5.obj"/>
      </geometry>
      <material name="rizon_light_grey"/>
    </visual>
    <collision>
      <origin rpy="0 0 0" xyz="0 0 0"/>
      <geometry>
        <mesh filename="../meshes/link5_collision.stl"/>
      </geometry>
    </collision>
  </link>
  <link name="link6">
    <inertial>
      <mass value="2.1"/>
      <origin rpy="0 0 0" xyz="-0.01 0.06 0.07"/>
      <inertia ixx="0.01" ixy="-0.0" ixz="-0.001" iyy="0.01" iyz="0.0" izz="0.0"/>
    </inertial>
    <visual>
      <origin rpy="0 0 0" xyz="0 0 0"/>
      <geometry>
        <mesh filename="../meshes/link6.obj"/>
      </geometry>
      <material name="rizon_light_grey"/>
    </visual>
    <collision>
      <origin rpy="0 0 0" xyz="0 0 0"/>
      <geometry>
        <mesh filename="../meshes/link6_collision.stl"/>
      </geometry>
    </collision>
  </link>
  <link name="link7">
    <inertial>
      <mass value="0.8"/>
      <origin rpy="0 0 0" xyz="0.0 0.0 0.03"/>
      <inertia ixx="0.0" ixy="0.0" ixz="0.0" iyy="0.0" iyz="0.0" izz="0.0"/>
    </inertial>
    <visual>
      <origin rpy="0 0 0" xyz="0 0 0"/>
      <geometry>
        <mesh filename="../meshes/link7.obj"/>
      </geometry>
      <material name="rizon_light_grey"/>
    </visual>
    <collision>
      <origin rpy="0 0 0" xyz="0 0 0"/>
      <geometry>
        <mesh filename="../meshes/link7_collision.stl"/>
      </geometry>
    </collision>
  </link>
  <link name="flange"/>
  <ros2_control name="FlexivHardwareInterface" type="system">
    <hardware>
      <plugin>flexiv_hardware/FlexivHardwareInterface</plugin>
      <param name="robot_ip"></param>
      <param name="local_ip"></param>
    </hardware>
    <joint name="joint1">
      <command_interface name="position">
        <param name="min">-2.7925</param>
        <param name="max">2.7925</param>
      </command_interface>
      <command_interface name="velocity">
        <param name="min">-2.0944</param>
        <param name="max">2.0944</param>
      </command_interface>
      <command_interface name="effort"/>
      <state_interface name="position"/>
      <state_interface name="velocity"/>
      <state_interface name="effort"/>
      <param name="initial_position">0.0</param>
      <!-- initial position for the FakeSystem -->
    </joint>
    <joint name="joint2">
      <command_interface name="position">
        <param name="min">-2.2689</param>
        <param name="max">2.2689</param>
      </command_interface>
      <command_interface name="velocity">
        <param name="min">-2.0944</param>
        <param name="max">2.0944</param>
      </command_interface>
      <command_interface name="effort"/>
      <state_interface name="position"/>
      <state_interface name="velocity"/>
      <state_interface name="effort"/>
      <param name="initial_position">-0.69813</param>
      <!-- initial position for the FakeSystem -->
    </joint>
    <joint name="joint3">
      <command_interface name="position">
        <param name="min">-2.9671</param>
        <param name="max">2.9671</param>
      </command_interface>
      <command_interface name="velocity">
        <param name="min">-2.4435</param>
        <param name="max">2.4435</param>
      </command_interface>
      <command_interface name="effort"/>
      <state_interface name="position"/>
      <state_interface name="velocity"/>
      <state_interface name="effort"/>
      <param name="initial_position">0.0</param>
      <!-- initial position for the FakeSystem -->
    </joint>
    <joint name="joint4">
      <command_interface name="position">
        <param name="min">-1.8675</param>
        <param name="max">2.6878</param>
      </command_interface>
      <command_interface name="velocity">
        <param name="min">-2.4435</param>
        <param name="max">2.4435</param>
      </command_interface>
      <command_interface name="effort"/>
      <state_interface name="position"/>
      <state_interface name="velocity"/>
      <state_interface name="effort"/>
      <param name="initial_position">1.570796</param>
      <!-- initial position for the FakeSystem -->
    </joint>
    <joint name="joint5">
      <command_interface name="position">
        <param name="min">-2.9671</param>
        <param name="max">2.9671</param>
      </command_interface>
      <command_interface name="velocity">
        <param name="min">-4.8869</param>
        <param name="max">4.8869</param>
      </command_interface>
      <command_interface name="effort"/>
      <state_interface name="position"/>
      <state_interface name="velocity"/>
      <state_interface name="effort"/>
      <param name="initial_position">0.0</param>
      <!-- initial position for the FakeSystem -->
    </joint>
    <joint name="joint6">
      <command_interface name="position">
        <param name="min">-1.3963</param>
        <param name="max">4.5379</param>
      </command_interface>
      <command_interface name="velocity">
        <param name="min">-4.8869</param>
        <param name="max">4.8869</param>
      </command_interface>
      <command_interface name="effort"/>
      <state_interface name="position"/>
      <state_interface name="velocity"/>
      <state_interface name="effort"/>
      <param name="initial_position">0.69813</param>
      <!-- initial position for the FakeSystem -->
    </joint>
    <joint name="joint7">
      <command_interface name="position">
        <param name="min">-2.9671</param>
        <param name="max">2.9671</param>
      </command_interface>
      <command_interface name="velocity">
        <param name="min">-4.8869</param>
        <param name="max">4.8869</param>
      </command_interface>
      <command_interface name="effort"/>
      <state_interface name="position"/>
      <state_interface name="velocity"/>
      <state_interface name="effort"/>
      <param name="initial_position">0.0</param>
      <!-- initial position for the FakeSystem -->
    </joint>
  </ros2_control>
</robot>
